<?xml version="1.0" encoding="utf-8"?>
<!-- This URDF was automatically created by SolidWorks to URDF Exporter! Originally created by Stephen Brawner (brawner@gmail.com) 
     Commit Version: 1.6.0-4-g7f85cfe  Build Version: 1.6.7995.38578
     For more information, please see http://wiki.ros.org/sw_urdf_exporter -->
<robot
  name="obstacle_bot">

  <link
    name="Base">
    <inertial>
      <origin
        xyz="0 0 0.02"
        rpy="0 0 0" />
      <mass
        value="0.2" />
      <inertia
        ixx="0.0002"
        ixy="0"
        ixz="0"
        iyy="0.0002"
        iyz="0"
        izz="0.0003" />
    </inertial>
    <visual>
      <origin
        xyz="0 0 0.02"
        rpy="0 0 0" />
      <geometry>
        <box size="0.08 0.08 0.04"/>
      </geometry>
      <material
        name="">
        <color
          rgba="1 1 1 0.3" />
      </material>
    </visual>
    <collision>
      <origin
        xyz="0 0 0.02"
        rpy="0 0 0" />
      <geometry>
        <box size="0.08 0.08 0.04"/>
      </geometry>
    </collision>
  </link>

  <!-- Right wheel -->

  <link
    name="Right_wheel">
    <inertial>
      <origin
        xyz="0 0 0"
        rpy="0 0 0" />
      <mass
        value="0.05" />
      <inertia
        ixx="0.00001"
        ixy="0"
        ixz="0"
        iyy="0.00001"
        iyz="0"
        izz="0.00001" />
    </inertial>
    <visual>
      <origin
        xyz="0 0 0"
        rpy="0 0 0" />
      <geometry>
        <cylinder radius="0.017" length="0.006"/>
      </geometry>
      <material
        name="">
        <color
          rgba="0.792156862745098 0.819607843137255 0.933333333333333 1" />
      </material>
    </visual>
    <collision>
      <origin
        xyz="0 0 0"
        rpy="0 0 0" />
      <geometry>
        <cylinder radius="0.017" length="0.006"/>
      </geometry>
    </collision>
  </link>

  <joint
    name="Right_wheel_joint"
    type="continuous">
    <origin
      xyz="0 -0.0403 0.008"
      rpy="1.5708 0 0" />
    <parent
      link="Base" />
    <child
      link="Right_wheel" />
    <axis
      xyz="0 0 1" />
    <dynamics damping="0.1" friction="0.1"/>
  </joint>

  <!-- Left wheel -->

  <link
    name="Left_wheel">
    <inertial>
      <origin
        xyz="0 0 0"
        rpy="0 0 0" />
      <mass
        value="0.05" />
      <inertia
        ixx="0.00001"
        ixy="0"
        ixz="0"
        iyy="0.00001"
        iyz="0"
        izz="0.00001" />
    </inertial>
    <visual>
      <origin
        xyz="0 0 0"
        rpy="0 0 0" />
      <geometry>
        <cylinder radius="0.017" length="0.006"/>
      </geometry>
      <material
        name="">
        <color
          rgba="0.792156862745098 0.819607843137255 0.933333333333333 1" />
      </material>
    </visual>
    <collision>
      <origin
        xyz="0 0 0"
        rpy="0 0 0" />
      <geometry>
        <cylinder radius="0.017" length="0.006"/>
      </geometry>
    </collision>
  </link>

  <joint
    name="Left_wheel_joint"
    type="continuous">
    <origin
      xyz="0 0.0403 0.008"
      rpy="1.5708 0 0" />
    <parent
      link="Base" />
    <child
      link="Left_wheel" />
    <axis
      xyz="0 0 1" />
    <dynamics damping="0.1" friction="0.1"/>
  </joint>

  <!-- Caster wheel -->

  <link
    name="Caster_wheel">
    <inertial>
      <origin
        xyz="0 0 0"
        rpy="0 0 0" />
      <mass
        value="0.01" />
      <inertia
        ixx="0.000001"
        ixy="0"
        ixz="0"
        iyy="0.000001"
        iyz="0"
        izz="0.000001" />
    </inertial>
    <visual>
      <origin
        xyz="0 0 0"
        rpy="0 0 0" />
      <geometry>
        <sphere radius="0.008"/>
      </geometry>
      <material
        name="">
        <color
          rgba="0.2 0.2 0.2 1" />
      </material>
    </visual>
    <collision>
      <origin
        xyz="0 0 0"
        rpy="0 0 0" />
      <geometry>
        <sphere radius="0.008"/>
      </geometry>
    </collision>
  </link>

  <joint
    name="Caster_wheel_joint"
    type="fixed">
    <origin
      xyz="0.03 0 0"
      rpy="0 0 0" />
    <parent
      link="Base" />
    <child
      link="Caster_wheel" />
  </joint>
</robot>
